Workbook

Sheet README
A1: Appendix — Computational workbook for "Computational, Communication and Scheduling Limits of MMC Control Architectures"
A3: Purpose | B3: Every numerical figure and every plot of the report is reproduced here as a live formula. Change an input (blue cells, yellow fill) and all sheets, tables and charts recalculate.
A4: Colour code | B4: Blue text on yellow = input / assumption (design estimate pending DWT-CYCCNT measurement unless a reference is cited). Black = formula. Green = link to another sheet.
A5: Units | B5: Cycles at f_CPU; times in µs unless stated; utilization stored as fraction (0.17 = 17 %).
A6: Sheet map | B6: Parameters → §2 Cost models → §2.5 Budget method → §3 Case A → §4 Case B → §5 Case C → §6 Scaling laws → §7 Scheduling → §8 Comparative → §9 Harmonics
A7: Equation column | B7: Each computed column carries, in its header, the symbolic equation it implements so the sheet can be read as a derivation.
A8: References | B8: [1] Ricco, Mathe, Teodorescu, EPE ECCE Europe (Bitonic sorting on FPGA) · [3] ISO 11898 CAN · [5] IEEE 802.3 · [7] Xilinx PG046 Aurora 8B/10B · [8] ST RM0440 STM32G4 · [10],[11] Olfati-Saber et al. consensus · [12] Liu & Layland 1973 · [13] Buttazzo · [14] ARM Cortex-M4 TRM · [15] IEEE 519-2022

Sheet Parameters
A1: Global parameters and cost model (inputs)
A2: All blue cells are inputs. Every other sheet references this sheet.
A4: Symbol | B4: Meaning | C4: Value | D4: Unit | E4: Source / note
A5: f_CPU | B5: STM32G474 core clock | C5: 170000000 | D5: Hz | E5: [8] RM0440
A6: T1 | B6: CVB / low-level period | C6: 0.0001 | D6: s | E6: project task set (10 kHz)
A7: T2 | B7: energy / inner period | C7: 0.001 | D7: s | E7: project task set (1 kHz)
A8: T3 | B8: grid / outer period | C8: 0.01 | D8: s | E8: project task set (100 Hz)
A9: f0 | B9: grid frequency | C9: 50 | D9: Hz
A10: b | B10: payload bits per measurement frame | C10: 32 | D10: bit | E10: Vc 12–16 bit + ID + status
A11: N_ref | B11: reference submodules per arm (whiteboard) | C11: 15 | D11: - | E11: project
A12: U_max | B12: RMS bound, harmonic set | C12: 1 | D12: - | E12: [12]
A13: U_design | B13: design margin on utilization | C13: 0.7 | D13: - | E13: report §7
A14: c_FLOP | B14: FADD/FSUB/FMUL/FMA | C14: 3 | D14: cyc | E14: [14] adjusted
A15: c_DIV | B15: FDIV / FSQRT | C15: 14 | D15: cyc | E15: [14]
A16: c_TRIG | B16: sin / cos (CMSIS table) | C16: 50 | D16: cyc
A17: c_TANH | B17: tanh polynomial | C17: 60 | D17: cyc
A18: c_MOD | B18: floating mod | C18: 20 | D18: cyc
A19: c_STATE | B19: persistent state access | C19: 4 | D19: cyc/var
A20: c_CALL | B20: function overhead | C20: 40 | D20: cyc
A21: c_CS | B21: compare-and-swap, packed word (bubble) | C21: 12 | D21: cyc | E21: design estimate — Case A
A22: c_SEL | B22: selection / gate write per module | C22: 11 | D22: cyc | E22: design estimate — Case A
A23: C0_A | B23: CVB fixed overhead Case A | C23: 50 | D23: cyc
A24: a2 | B24: energy layer fixed cycles (centralized) | C24: 200 | D24: cyc | E24: extracted code
A25: b2 | B25: energy layer cycles per module | C25: 19 | D25: cyc/SM | E25: mean + ΣE over N
A26: C3 | B26: outer layer cycles (2 SOGI, PLL, dq PI, power) | C26: 800 | D26: cyc | E26: NLMsortclose7 extracted
A27: C3_CORDIC | B27: outer layer with CORDIC | C27: 680 | D27: cyc | E27: 4 trig 200→80
A28: t_SPI | B28: SPI 20 MHz frame time, b=32 | C28: 3.6e-06 | D28: s | E28: Table 3: b/20M + 2 µs
A29: t_UART | B29: UART 8N1 3 Mbps frame, 4 bytes | C29: =10*CEILING(C10/8,1)/3000000 -> 1.3333333e-05 | D29: s | E29: formula: 10·⌈b/8⌉/3e6
A30: t_AUR | B30: Aurora stream interval per sample | C30: 4e-08 | D30: s | E30: [7], project stream model
A31: t_gate | B31: gate distribution frame per arm (1 bit/SM, N≤32) | C31: 3.6e-06 | D31: s | E31: one 32-bit SPI frame
A32: C1_C | B32: decentralized τ1 per node | C32: 970 | D32: cyc | E32: 260 consensus + 150 frame + 560 gate/health
A33: C2_C | B33: decentralized τ2 replica | C33: 220 | D33: cyc
A34: C3_C | B34: decentralized τ3 replica | C34: 800 | D34: cyc
A35: k_v | B35: consensus gain | C35: 0.2 | D35: 1/V | E35: project model
A36: t_fw | B36: per-hop forwarding overhead on the ring | C36: 1.67e-06 | D36: s | E36: so that (t_UART+t_fw)/2 ≈ 7.5 µs
A37: f_FPGA | B37: FPGA clock | C37: 100000000 | D37: Hz | E37: [1]
A38: LUT_dev | B38: LUTs of Spartan-6 XC6SLX45 | C38: 27288 | D38: LUT | E38: Xilinx DS160
A39: LUT_64 | B39: LUTs for six arms of 64 (validated) | C39: 6200 | D39: LUT | E39: [1]
A40: LUT_A7 | B40: LUTs of Artix-7 XC7A35T | C40: 20800 | D40: LUT | E40: Xilinx DS180
A41: k_THD | B41: staircase THD coefficient | C41: 0.816 | D41: - | E41: THD ≈ 0.816/N
...

Sheet §2 Cost models
A1: §2.2–2.3 Processor cost model and communication frame models
A4: Protocol | B4: Frame-time model (payload b bits) | C4: t_frame (s) — formula | D4: t_frame (µs) | E4: Ref
A5: CAN 2.0, 1 Mbps | B5: (47 + b)·1.19 / 1e6 (worst-case stuffing) | C5: =(47+Parameters!$C$10)*1.19/1000000 -> 9.401e-05 | D5: =C5*1000000 -> 94.01 | E5: [3]
A6: CAN FD, 5 Mbps data | B6: 29/1e6 + (b + 28)/5e6 | C6: =29/1000000+(Parameters!$C$10+28)/5000000 -> 4.1e-05 | D6: =C6*1000000 -> 41 | E6: [3]
A7: UART 8N1, 3 Mbps | B7: 10·⌈b/8⌉ / 3e6 | C7: =10*CEILING(Parameters!$C$10/8,1)/3000000 -> 1.3333333e-05 | D7: =C7*1000000 -> 13.333333
A8: SPI, 20 MHz | B8: b/20e6 + 2 µs (CS + service) | C8: =Parameters!$C$10/20000000+0.000002 -> 3.6e-06 | D8: =C8*1000000 -> 3.6
A9: Ethernet 100M | B9: max(672, b + 336)/100e6 | C9: =MAX(672,Parameters!$C$10+336)/100000000 -> 6.72e-06 | D9: =C9*1000000 -> 6.72 | E9: [5]
A10: Aurora 8B/10B, 3.125 G | B10: b/2.5e9 + 40 ns | C10: =Parameters!$C$10/2500000000+0.00000004 -> 5.28e-08 | D10: =C10*1000000 -> 0.0528 | E10: [7]
A13: Bus load on a shared bus: ρ(N) = 2N·t_frame / T1 (must stay < ~0.5, [4])
A14: N | B14: ρ SPI | C14: ρ UART | D14: ρ CAN FD | E14: ρ Ethernet
A15: 4 | B15: =2*A15*$C$8/Parameters!$C$6 -> 0.288 | C15: =2*A15*$C$7/Parameters!$C$6 -> 1.0666667 | D15: =2*A15*$C$6/Parameters!$C$6 -> 3.28 | E15: =2*A15*$C$9/Parameters!$C$6 -> 0.5376
A16: 8 | B16: =2*A16*$C$8/Parameters!$C$6 -> 0.576 | C16: =2*A16*$C$7/Parameters!$C$6 -> 2.1333333 | D16: =2*A16*$C$6/Parameters!$C$6 -> 6.56 | E16: =2*A16*$C$9/Parameters!$C$6 -> 1.0752
A17: 12 | B17: =2*A17*$C$8/Parameters!$C$6 -> 0.864 | C17: =2*A17*$C$7/Parameters!$C$6 -> 3.2 | D17: =2*A17*$C$6/Parameters!$C$6 -> 9.84 | E17: =2*A17*$C$9/Parameters!$C$6 -> 1.6128
A18: 15 | B18: =2*A18*$C$8/Parameters!$C$6 -> 1.08 | C18: =2*A18*$C$7/Parameters!$C$6 -> 4 | D18: =2*A18*$C$6/Parameters!$C$6 -> 12.3 | E18: =2*A18*$C$9/Parameters!$C$6 -> 2.016
A19: 16 | B19: =2*A19*$C$8/Parameters!$C$6 -> 1.152 | C19: =2*A19*$C$7/Parameters!$C$6 -> 4.2666667 | D19: =2*A19*$C$6/Parameters!$C$6 -> 13.12 | E19: =2*A19*$C$9/Parameters!$C$6 -> 2.1504
A20: 24 | B20: =2*A20*$C$8/Parameters!$C$6 -> 1.728 | C20: =2*A20*$C$7/Parameters!$C$6 -> 6.4 | D20: =2*A20*$C$6/Parameters!$C$6 -> 19.68 | E20: =2*A20*$C$9/Parameters!$C$6 -> 3.2256
A21: 32 | B21: =2*A21*$C$8/Parameters!$C$6 -> 2.304 | C21: =2*A21*$C$7/Parameters!$C$6 -> 8.5333333 | D21: =2*A21*$C$6/Parameters!$C$6 -> 26.24 | E21: =2*A21*$C$9/Parameters!$C$6 -> 4.3008
A24: Calibrated layer cost laws (cycles per period)
A25: Layer / variant | B25: Equation | C25: Parameters used | D25: Value at N_ref | E25: Note
A26: CVB bubble, both arms | B26: C1 = c_CS·N(N−1) + 2·c_SEL·N + C0 = 12N² + 10N + 50 | C26: c_CS, c_SEL, C0_A | D26: =Parameters!$C$21*Parameters!$C$11*(Parameters!$C$11-1)+2*Parameters!$C$22*Parameters!$C$11+Parameters!$C$23 -> 2900 | E26: bubble: N(N−1)/2 CS per arm (Knuth TAOCP 3 §5.2.2)
A27: CVB merge-class, both arms | B27: C1 = 40·N·log2 N + 10N + 50 | D27: =40*Parameters!$C$11*LOG(Parameters!$C$11,2)+10*Parameters!$C$11+50 -> 2544.1344
A28: CVB min/max scan (±1 rule) | B28: C1 = 200 + 6N | D28: =200+6*Parameters!$C$11 -> 290
A29: Energy layer, centralized | B29: C2 = a2 + b2·N = 200 + 19N | C29: a2, b2 | D29: =Parameters!$C$24+Parameters!$C$25*Parameters!$C$11 -> 485 | E29: mean and ΣE over N are O(N)
A30: Outer layer | B30: C3 = 800 (O(1)) | C30: C3 | D30: =Parameters!$C$26 -> 800
A31: Decentralized τ1 per node | B31: C1 = 970 const | C31: C1_C | D31: =Parameters!$C$32 -> 970
A32: Decentralized τ2 per node | B32: C2 = 220 const | C32: C2_C | D32: =Parameters!$C$33 -> 220
A33: Decentralized τ3 per node | B33: C3 = 800 const | C33: C3_C | D33: =Parameters!$C$34 -> 800

Sheet §2.5 Budget method
A1: §2.5 How each task budget is computed — five steps, three cases
A4: Step | B4: Equation | C4: A : MCU + bubble (N_ref) | D4: B : FPGA + Bitonic (M = 16) | E4: C : Decentralized (any N)
A5: (1) Budget B1 (cyc) | B5: B_i = f_CPU · T_i | C5: =Parameters!$C$5*Parameters!$C$6 -> 17000 | D5: n/a (always-on pipelines) | E5: =Parameters!$C$5*Parameters!$C$6 -> 17000
A6: (1) Budget B2 (cyc) | C6: =Parameters!$C$5*Parameters!$C$7 -> 170000 | D6: n/a | E6: =Parameters!$C$5*Parameters!$C$7 -> 170000
A7: (1) Budget B3 (cyc) | C7: =Parameters!$C$5*Parameters!$C$8 -> 1700000 | D7: n/a | E7: =Parameters!$C$5*Parameters!$C$8 -> 1700000
A8: (2) Cost C1 (cyc) | B8: operation count × Table 2 | C8: =INDEX('§3 Case A'!B5:B47,MATCH(Parameters!C11,'§3 Case A'!A5:A47,0)) -> 2900 | D8: ='§4 Case B'!F6 -> 0.44 | E8: =Parameters!$C$32 -> 970
A9: (2) Cost C2 (cyc) | C9: =INDEX('§3 Case A'!D5:D47,MATCH(Parameters!C11,'§3 Case A'!A5:A47,0)) -> 485 | D9: sub-µs HW | E9: =Parameters!$C$33 -> 220
A10: (2) Cost C3 (cyc) | C10: =Parameters!$C$26 -> 800 | D10: sub-µs HW | E10: =Parameters!$C$34 -> 800
A11: (2) t1 (µs) | B11: t_i = C_i / f_CPU | C11: =C8/Parameters!$C$5*1000000 -> 17.058824 | D11: ='§4 Case B'!F6 -> 0.44 | E11: =E8/Parameters!$C$5*1000000 -> 5.7058824
A12: (3) Utilization U | B12: U = Σ C_i/(f_CPU·T_i) ≤ U_max | C12: =C8/C5+C9/C6+C10/C7 -> 0.17391176 | D12: ='§4 Case B'!H6 -> 0.0192 | E12: =E8/E5+E9/E6+E10/E7 -> 0.058823529
A13: (4) T_acq (µs) | B13: N·t_SPI (dual) / 2N·t_AUR / t_UART (2 links parallel) | C13: =Parameters!$C$11*Parameters!$C$28*1000000 -> 54 | D13: =2*Parameters!$C$11*Parameters!$C$30*1000000 -> 1.2 | E13: =Parameters!$C$29*1000000 -> 13.333333
A14: (4) Deadline path (µs) | B14: T_path = T_acq + t1 ≤ T1 | C14: =C13+C11 -> 71.058824 | D14: =D13+D11+0.2 -> 1.84 | E14: =E13+E11 -> 19.039216
A15: (4) Slack (µs) | B15: T1 − T_path | C15: =Parameters!$C$6*1000000-C14 -> 28.941176 | D15: =Parameters!$C$6*1000000-D14 -> 98.16 | E15: =Parameters!$C$6*1000000-E14 -> 80.960784
A16: (4) Makespan at critical instant (µs) | B16: T_acq + t1 + t2 + t3 | C16: =C13+C11+C9/Parameters!$C$5*1000000+C10/Parameters!$C$5*1000000 -> 78.617647 | D16: pipelines in parallel | E16: =E13+E11+E9/Parameters!$C$5*1000000+E10/Parameters!$C$5*1000000 -> 25.039216
A17: (5) T_dist (µs) | B17: one gate frame per arm / 0 (fabric) / 0 (self-gating) | C17: =Parameters!$C$31*1000000 -> 3.6 | D17: 0 | E17: 0
A18: (5) Actuation latency (µs) | B18: T_act = T_acq + t1 + T_dist | C18: =C14+C17 -> 74.658824 | D18: =D14+D17 -> 1.84 | E18: =E14+E17 -> 19.039216
A19: N_max rule | B19: largest N passing (3) and (4) | C19: ='§3 Case A'!G52&" (shared bus) / "&'§3 Case A'!G53&" (dual bus) / "&'§3 Case A'!G54&" (compute only)" -> 12 (shared bus) / 19 (dual bus) / 37 (compute only) | D19: ≈128 (LUT ≤ device) | E19: 64–90 (τ_conv ≤ 50 ms, pure ring)

Sheet §3 Case A
A1: §3 Case A — Centralized MCU + bubble sort: N sweep
A2: Budget B1 = f_CPU·T1 ; times t = C/f_CPU ; DMA occupies the link not the CPU.
A4: N | B4: C1 bubble (cyc) = 12N²+10N+50 | C4: C1 merge (cyc) = 40N·log2N+10N+50 | D4: C2 (cyc) = 200+19N | E4: C3 (cyc) | F4: t1 (µs) = C1/f_CPU | G4: t2 (µs) | H4: t3 (µs) | I4: T_acq single bus (µs) = 2N·t_SPI | J4: T_acq dual bus (µs) = N·t_SPI | K4: U_DMA = C1/B1 + C2/B2 + C3/B3 | L4: U_block = U_DMA + 2N·t_SPI/T1 | M4: Path single = T_acq + t1 (µs) | N4: Path dual = N·t_SPI + t1 (µs) | O4: Makespan dual = T_acq + t1 + t2 + t3 (µs) | P4: Actuation dual = T_acq + t1 + t_gate (µs) | Q4: Slack dual = T1 − path (µs) | R4: PASS single (path ≤ T1) | S4: PASS dual (path ≤ T1) | T4: PASS compute only (U_DMA ≤ U_max) | U4: U merge (DMA)
A5: 4 | B5: =Parameters!$C$21*A5*(A5-1)+2*Parameters!$C$22*A5+Parameters!$C$23 -> 282 | C5: =40*A5*LOG(A5,2)+10*A5+50 -> 410 | D5: =Parameters!$C$24+Parameters!$C$25*A5 -> 276 | E5: =Parameters!$C$26 -> 800 | F5: =B5/Parameters!$C$5*1000000 -> 1.6588235 | G5: =D5/Parameters!$C$5*1000000 -> 1.6235294 | H5: =E5/Parameters!$C$5*1000000 -> 4.7058824 | I5: =2*A5*Parameters!$C$28*1000000 -> 28.8 | J5: =A5*Parameters!$C$28*1000000 -> 14.4 | K5: =B5/(Parameters!$C$5*Parameters!$C$6)+D5/(Parameters!$C$5*Parameters!$C$7)+E5/(Parameters!$C$5*Parameters!$C$8) -> 0.018682353 | L5: =K5+2*A5*Parameters!$C$28/Parameters!$C$6 -> 0.30668235 | M5: =I5+F5 -> 30.458824 | N5: =J5+F5 -> 16.058824 | O5: =J5+F5+G5+H5 -> 22.388235 | P5: =J5+F5+Parameters!$C$31*1000000 -> 19.658824 | Q5: =Parameters!$C$6*1000000-N5 -> 83.941176 | R5: =IF(M5<=Parameters!$C$6*1000000,1,0) -> 1 | S5: =IF(N5<=Parameters!$C$6*1000000,1,0) -> 1 | T5: =IF(K5<=Parameters!$C$12,1,0) -> 1 | U5: =C5/(Parameters!$C$5*Parameters!$C$6)+D5/(Parameters!$C$5*Parameters!$C$7)+E5/(Parameters!$C$5*Parameters!$C$8) -> 0.026211765
A6: 5 | B6: =Parameters!$C$21*A6*(A6-1)+2*Parameters!$C$22*A6+Parameters!$C$23 -> 400 | C6: =40*A6*LOG(A6,2)+10*A6+50 -> 564.38562 | D6: =Parameters!$C$24+Parameters!$C$25*A6 -> 295 | E6: =Parameters!$C$26 -> 800 | F6: =B6/Parameters!$C$5*1000000 -> 2.3529412 | G6: =D6/Parameters!$C$5*1000000 -> 1.7352941 | H6: =E6/Parameters!$C$5*1000000 -> 4.7058824 | I6: =2*A6*Parameters!$C$28*1000000 -> 36 | J6: =A6*Parameters!$C$28*1000000 -> 18 | K6: =B6/(Parameters!$C$5*Parameters!$C$6)+D6/(Parameters!$C$5*Parameters!$C$7)+E6/(Parameters!$C$5*Parameters!$C$8) -> 0.025735294 | L6: =K6+2*A6*Parameters!$C$28/Parameters!$C$6 -> 0.38573529 | M6: =I6+F6 -> 38.352941 | N6: =J6+F6 -> 20.352941 | O6: =J6+F6+G6+H6 -> 26.794118 | P6: =J6+F6+Parameters!$C$31*1000000 -> 23.952941 | Q6: =Parameters!$C$6*1000000-N6 -> 79.647059 | R6: =IF(M6<=Parameters!$C$6*1000000,1,0) -> 1 | S6: =IF(N6<=Parameters!$C$6*1000000,1,0) -> 1 | T6: =IF(K6<=Parameters!$C$12,1,0) -> 1 | U6: =C6/(Parameters!$C$5*Parameters!$C$6)+D6/(Parameters!$C$5*Parameters!$C$7)+E6/(Parameters!$C$5*Parameters!$C$8) -> 0.035405036
A7: 6 | B7: =Parameters!$C$21*A7*(A7-1)+2*Parameters!$C$22*A7+Parameters!$C$23 -> 542 | C7: =40*A7*LOG(A7,2)+10*A7+50 -> 730.391 | D7: =Parameters!$C$24+Parameters!$C$25*A7 -> 314 | E7: =Parameters!$C$26 -> 800 | F7: =B7/Parameters!$C$5*1000000 -> 3.1882353 | G7: =D7/Parameters!$C$5*1000000 -> 1.8470588 | H7: =E7/Parameters!$C$5*1000000 -> 4.7058824 | I7: =2*A7*Parameters!$C$28*1000000 -> 43.2 | J7: =A7*Parameters!$C$28*1000000 -> 21.6 | K7: =B7/(Parameters!$C$5*Parameters!$C$6)+D7/(Parameters!$C$5*Parameters!$C$7)+E7/(Parameters!$C$5*Parameters!$C$8) -> 0.0342 | L7: =K7+2*A7*Parameters!$C$28/Parameters!$C$6 -> 0.4662 | M7: =I7+F7 -> 46.388235 | N7: =J7+F7 -> 24.788235 | O7: =J7+F7+G7+H7 -> 31.341176 | P7: =J7+F7+Parameters!$C$31*1000000 -> 28.388235 | Q7: =Parameters!$C$6*1000000-N7 -> 75.211765 | R7: =IF(M7<=Parameters!$C$6*1000000,1,0) -> 1 | S7: =IF(N7<=Parameters!$C$6*1000000,1,0) -> 1 | T7: =IF(K7<=Parameters!$C$12,1,0) -> 1 | U7: =C7/(Parameters!$C$5*Parameters!$C$6)+D7/(Parameters!$C$5*Parameters!$C$7)+E7/(Parameters!$C$5*Parameters!$C$8) -> 0.045281824
A8: 7 | B8: =Parameters!$C$21*A8*(A8-1)+2*Parameters!$C$22*A8+Parameters!$C$23 -> 708 | C8: =40*A8*LOG(A8,2)+10*A8+50 -> 906.05938 | D8: =Parameters!$C$24+Parameters!$C$25*A8 -> 333 | E8: =Parameters!$C$26 -> 800 | F8: =B8/Parameters!$C$5*1000000 -> 4.1647059 | G8: =D8/Parameters!$C$5*1000000 -> 1.9588235 | H8: =E8/Parameters!$C$5*1000000 -> 4.7058824 | I8: =2*A8*Parameters!$C$28*1000000 -> 50.4 | J8: =A8*Parameters!$C$28*1000000 -> 25.2 | K8: =B8/(Parameters!$C$5*Parameters!$C$6)+D8/(Parameters!$C$5*Parameters!$C$7)+E8/(Parameters!$C$5*Parameters!$C$8) -> 0.044076471 | L8: =K8+2*A8*Parameters!$C$28/Parameters!$C$6 -> 0.54807647 | M8: =I8+F8 -> 54.564706 | N8: =J8+F8 -> 29.364706 | O8: =J8+F8+G8+H8 -> 36.029412 | P8: =J8+F8+Parameters!$C$31*1000000 -> 32.964706 | Q8: =Parameters!$C$6*1000000-N8 -> 70.635294 | R8: =IF(M8<=Parameters!$C$6*1000000,1,0) -> 1 | S8: =IF(N8<=Parameters!$C$6*1000000,1,0) -> 1 | T8: =IF(K8<=Parameters!$C$12,1,0) -> 1 | U8: =C8/(Parameters!$C$5*Parameters!$C$6)+D8/(Parameters!$C$5*Parameters!$C$7)+E8/(Parameters!$C$5*Parameters!$C$8) -> 0.055727022
A9: 8 | B9: =Parameters!$C$21*A9*(A9-1)+2*Parameters!$C$22*A9+Parameters!$C$23 -> 898 | C9: =40*A9*LOG(A9,2)+10*A9+50 -> 1090 | D9: =Parameters!$C$24+Parameters!$C$25*A9 -> 352 | E9: =Parameters!$C$26 -> 800 | F9: =B9/Parameters!$C$5*1000000 -> 5.2823529 | G9: =D9/Parameters!$C$5*1000000 -> 2.0705882 | H9: =E9/Parameters!$C$5*1000000 -> 4.7058824 | I9: =2*A9*Parameters!$C$28*1000000 -> 57.6 | J9: =A9*Parameters!$C$28*1000000 -> 28.8 | K9: =B9/(Parameters!$C$5*Parameters!$C$6)+D9/(Parameters!$C$5*Parameters!$C$7)+E9/(Parameters!$C$5*Parameters!$C$8) -> 0.055364706 | L9: =K9+2*A9*Parameters!$C$28/Parameters!$C$6 -> 0.63136471 | M9: =I9+F9 -> 62.882353 | N9: =J9+F9 -> 34.082353 | O9: =J9+F9+G9+H9 -> 40.858824 | P9: =J9+F9+Parameters!$C$31*1000000 -> 37.682353 | Q9: =Parameters!$C$6*1000000-N9 -> 65.917647 | R9: =IF(M9<=Parameters!$C$6*1000000,1,0) -> 1 | S9: =IF(N9<=Parameters!$C$6*1000000,1,0) -> 1 | T9: =IF(K9<=Parameters!$C$12,1,0) -> 1 | U9: =C9/(Parameters!$C$5*Parameters!$C$6)+D9/(Parameters!$C$5*Parameters!$C$7)+E9/(Parameters!$C$5*Parameters!$C$8) -> 0.066658824
A10: 9 | B10: =Parameters!$C$21*A10*(A10-1)+2*Parameters!$C$22*A10+Parameters!$C$23 -> 1112 | C10: =40*A10*LOG(A10,2)+10*A10+50 -> 1281.173 | D10: =Parameters!$C$24+Parameters!$C$25*A10 -> 371 | E10: =Parameters!$C$26 -> 800 | F10: =B10/Parameters!$C$5*1000000 -> 6.5411765 | G10: =D10/Parameters!$C$5*1000000 -> 2.1823529 | H10: =E10/Parameters!$C$5*1000000 -> 4.7058824 | I10: =2*A10*Parameters!$C$28*1000000 -> 64.8 | J10: =A10*Parameters!$C$28*1000000 -> 32.4 | K10: =B10/(Parameters!$C$5*Parameters!$C$6)+D10/(Parameters!$C$5*Parameters!$C$7)+E10/(Parameters!$C$5*Parameters!$C$8) -> 0.068064706 | L10: =K10+2*A10*Parameters!$C$28/Parameters!$C$6 -> 0.71606471 | M10: =I10+F10 -> 71.341176 | N10: =J10+F10 -> 38.941176 | O10: =J10+F10+G10+H10 -> 45.829412 | P10: =J10+F10+Parameters!$C$31*1000000 -> 42.541176 | Q10: =Parameters!$C$6*1000000-N10 -> 61.058824 | R10: =IF(M10<=Parameters!$C$6*1000000,1,0) -> 1 | S10: =IF(N10<=Parameters!$C$6*1000000,1,0) -> 1 | T10: =IF(K10<=Parameters!$C$12,1,0) -> 1 | U10: =C10/(Parameters!$C$5*Parameters!$C$6)+D10/(Parameters!$C$5*Parameters!$C$7)+E10/(Parameters!$C$5*Parameters!$C$8) -> 0.078016059
A11: 10 | B11: =Parameters!$C$21*A11*(A11-1)+2*Parameters!$C$22*A11+Parameters!$C$23 -> 1350 | C11: =40*A11*LOG(A11,2)+10*A11+50 -> 1478.7712 | D11: =Parameters!$C$24+Parameters!$C$25*A11 -> 390 | E11: =Parameters!$C$26 -> 800 | F11: =B11/Parameters!$C$5*1000000 -> 7.9411765 | G11: =D11/Parameters!$C$5*1000000 -> 2.2941176 | H11: =E11/Parameters!$C$5*1000000 -> 4.7058824 | I11: =2*A11*Parameters!$C$28*1000000 -> 72 | J11: =A11*Parameters!$C$28*1000000 -> 36 | K11: =B11/(Parameters!$C$5*Parameters!$C$6)+D11/(Parameters!$C$5*Parameters!$C$7)+E11/(Parameters!$C$5*Parameters!$C$8) -> 0.082176471 | L11: =K11+2*A11*Parameters!$C$28/Parameters!$C$6 -> 0.80217647 | M11: =I11+F11 -> 79.941176 | N11: =J11+F11 -> 43.941176 | O11: =J11+F11+G11+H11 -> 50.941176 | P11: =J11+F11+Parameters!$C$31*1000000 -> 47.541176 | Q11: =Parameters!$C$6*1000000-N11 -> 56.058824 | R11: =IF(M11<=Parameters!$C$6*1000000,1,0) -> 1 | S11: =IF(N11<=Parameters!$C$6*1000000,1,0) -> 1 | T11: =IF(K11<=Parameters!$C$12,1,0) -> 1 | U11: =C11/(Parameters!$C$5*Parameters!$C$6)+D11/(Parameters!$C$5*Parameters!$C$7)+E11/(Parameters!$C$5*Parameters!$C$8) -> 0.089751249
A12: 11 | B12: =Parameters!$C$21*A12*(A12-1)+2*Parameters!$C$22*A12+Parameters!$C$23 -> 1612 | C12: =40*A12*LOG(A12,2)+10*A12+50 -> 1682.1499 | D12: =Parameters!$C$24+Parameters!$C$25*A12 -> 409 | E12: =Parameters!$C$26 -> 800 | F12: =B12/Parameters!$C$5*1000000 -> 9.4823529 | G12: =D12/Parameters!$C$5*1000000 -> 2.4058824 | H12: =E12/Parameters!$C$5*1000000 -> 4.7058824 | I12: =2*A12*Parameters!$C$28*1000000 -> 79.2 | J12: =A12*Parameters!$C$28*1000000 -> 39.6 | K12: =B12/(Parameters!$C$5*Parameters!$C$6)+D12/(Parameters!$C$5*Parameters!$C$7)+E12/(Parameters!$C$5*Parameters!$C$8) -> 0.0977 | L12: =K12+2*A12*Parameters!$C$28/Parameters!$C$6 -> 0.8897 | M12: =I12+F12 -> 88.682353 | N12: =J12+F12 -> 49.082353 | O12: =J12+F12+G12+H12 -> 56.194118 | P12: =J12+F12+Parameters!$C$31*1000000 -> 52.682353 | Q12: =Parameters!$C$6*1000000-N12 -> 50.917647 | R12: =IF(M12<=Parameters!$C$6*1000000,1,0) -> 1 | S12: =IF(N12<=Parameters!$C$6*1000000,1,0) -> 1 | T12: =IF(K12<=Parameters!$C$12,1,0) -> 1 | U12: =C12/(Parameters!$C$5*Parameters!$C$6)+D12/(Parameters!$C$5*Parameters!$C$7)+E12/(Parameters!$C$5*Parameters!$C$8) -> 0.10182647
A13: 12 | B13: =Parameters!$C$21*A13*(A13-1)+2*Parameters!$C$22*A13+Parameters!$C$23 -> 1898 | C13: =40*A13*LOG(A13,2)+10*A13+50 -> 1890.782 | D13: =Parameters!$C$24+Parameters!$C$25*A13 -> 428 | E13: =Parameters!$C$26 -> 800 | F13: =B13/Parameters!$C$5*1000000 -> 11.164706 | G13: =D13/Parameters!$C$5*1000000 -> 2.5176471 | H13: =E13/Parameters!$C$5*1000000 -> 4.7058824 | I13: =2*A13*Parameters!$C$28*1000000 -> 86.4 | J13: =A13*Parameters!$C$28*1000000 -> 43.2 | K13: =B13/(Parameters!$C$5*Parameters!$C$6)+D13/(Parameters!$C$5*Parameters!$C$7)+E13/(Parameters!$C$5*Parameters!$C$8) -> 0.11463529 | L13: =K13+2*A13*Parameters!$C$28/Parameters!$C$6 -> 0.97863529 | M13: =I13+F13 -> 97.564706 | N13: =J13+F13 -> 54.364706 | O13: =J13+F13+G13+H13 -> 61.588235 | P13: =J13+F13+Parameters!$C$31*1000000 -> 57.964706 | Q13: =Parameters!$C$6*1000000-N13 -> 45.635294 | R13: =IF(M13<=Parameters!$C$6*1000000,1,0) -> 1 | S13: =IF(N13<=Parameters!$C$6*1000000,1,0) -> 1 | T13: =IF(K13<=Parameters!$C$12,1,0) -> 1 | U13: =C13/(Parameters!$C$5*Parameters!$C$6)+D13/(Parameters!$C$5*Parameters!$C$7)+E13/(Parameters!$C$5*Parameters!$C$8) -> 0.11421071
A14: 13 | B14: =Parameters!$C$21*A14*(A14-1)+2*Parameters!$C$22*A14+Parameters!$C$23 -> 2208 | C14: =40*A14*LOG(A14,2)+10*A14+50 -> 2104.2287 | D14: =Parameters!$C$24+Parameters!$C$25*A14 -> 447 | E14: =Parameters!$C$26 -> 800 | F14: =B14/Parameters!$C$5*1000000 -> 12.988235 | G14: =D14/Parameters!$C$5*1000000 -> 2.6294118 | H14: =E14/Parameters!$C$5*1000000 -> 4.7058824 | I14: =2*A14*Parameters!$C$28*1000000 -> 93.6 | J14: =A14*Parameters!$C$28*1000000 -> 46.8 | K14: =B14/(Parameters!$C$5*Parameters!$C$6)+D14/(Parameters!$C$5*Parameters!$C$7)+E14/(Parameters!$C$5*Parameters!$C$8) -> 0.13298235 | L14: =K14+2*A14*Parameters!$C$28/Parameters!$C$6 -> 1.0689824 | M14: =I14+F14 -> 106.58824 | N14: =J14+F14 -> 59.788235 | O14: =J14+F14+G14+H14 -> 67.123529 | P14: =J14+F14+Parameters!$C$31*1000000 -> 63.388235 | Q14: =Parameters!$C$6*1000000-N14 -> 40.211765 | R14: =IF(M14<=Parameters!$C$6*1000000,1,0) -> 0 | S14: =IF(N14<=Parameters!$C$6*1000000,1,0) -> 1 | T14: =IF(K14<=Parameters!$C$12,1,0) -> 1 | U14: =C14/(Parameters!$C$5*Parameters!$C$6)+D14/(Parameters!$C$5*Parameters!$C$7)+E14/(Parameters!$C$5*Parameters!$C$8) -> 0.12687816
A15: 14 | B15: =Parameters!$C$21*A15*(A15-1)+2*Parameters!$C$22*A15+Parameters!$C$23 -> 2542 | C15: =40*A15*LOG(A15,2)+10*A15+50 -> 2322.1188 | D15: =Parameters!$C$24+Parameters!$C$25*A15 -> 466 | E15: =Parameters!$C$26 -> 800 | F15: =B15/Parameters!$C$5*1000000 -> 14.952941 | G15: =D15/Parameters!$C$5*1000000 -> 2.7411765 | H15: =E15/Parameters!$C$5*1000000 -> 4.7058824 | I15: =2*A15*Parameters!$C$28*1000000 -> 100.8 | J15: =A15*Parameters!$C$28*1000000 -> 50.4 | K15: =B15/(Parameters!$C$5*Parameters!$C$6)+D15/(Parameters!$C$5*Parameters!$C$7)+E15/(Parameters!$C$5*Parameters!$C$8) -> 0.15274118 | L15: =K15+2*A15*Parameters!$C$28/Parameters!$C$6 -> 1.1607412 | M15: =I15+F15 -> 115.75294 | N15: =J15+F15 -> 65.352941 | O15: =J15+F15+G15+H15 -> 72.8 | P15: =J15+F15+Parameters!$C$31*1000000 -> 68.952941 | Q15: =Parameters!$C$6*1000000-N15 -> 34.647059 | R15: =IF(M15<=Parameters!$C$6*1000000,1,0) -> 0 | S15: =IF(N15<=Parameters!$C$6*1000000,1,0) -> 1 | T15: =IF(K15<=Parameters!$C$12,1,0) -> 1 | U15: =C15/(Parameters!$C$5*Parameters!$C$6)+D15/(Parameters!$C$5*Parameters!$C$7)+E15/(Parameters!$C$5*Parameters!$C$8) -> 0.13980699
A16: 15 | B16: =Parameters!$C$21*A16*(A16-1)+2*Parameters!$C$22*A16+Parameters!$C$23 -> 2900 | C16: =40*A16*LOG(A16,2)+10*A16+50 -> 2544.1344 | D16: =Parameters!$C$24+Parameters!$C$25*A16 -> 485 | E16: =Parameters!$C$26 -> 800 | F16: =B16/Parameters!$C$5*1000000 -> 17.058824 | G16: =D16/Parameters!$C$5*1000000 -> 2.8529412 | H16: =E16/Parameters!$C$5*1000000 -> 4.7058824 | I16: =2*A16*Parameters!$C$28*1000000 -> 108 | J16: =A16*Parameters!$C$28*1000000 -> 54 | K16: =B16/(Parameters!$C$5*Parameters!$C$6)+D16/(Parameters!$C$5*Parameters!$C$7)+E16/(Parameters!$C$5*Parameters!$C$8) -> 0.17391176 | L16: =K16+2*A16*Parameters!$C$28/Parameters!$C$6 -> 1.2539118 | M16: =I16+F16 -> 125.05882 | N16: =J16+F16 -> 71.058824 | O16: =J16+F16+G16+H16 -> 78.617647 | P16: =J16+F16+Parameters!$C$31*1000000 -> 74.658824 | Q16: =Parameters!$C$6*1000000-N16 -> 28.941176 | R16: =IF(M16<=Parameters!$C$6*1000000,1,0) -> 0 | S16: =IF(N16<=Parameters!$C$6*1000000,1,0) -> 1 | T16: =IF(K16<=Parameters!$C$12,1,0) -> 1 | U16: =C16/(Parameters!$C$5*Parameters!$C$6)+D16/(Parameters!$C$5*Parameters!$C$7)+E16/(Parameters!$C$5*Parameters!$C$8) -> 0.15297849
... A47: 256 | B47: =Parameters!$C$21*A47*(A47-1)+2*Parameters!$C$22*A47+Parameters!$C$23 -> 789042 | C47: =40*A47*LOG(A47,2)+10*A47+50 -> 84530 | D47: =Parameters!$C$24+Parameters!$C$25*A47 -> 5064 | E47: =Parameters!$C$26 -> 800 | F47: =B47/Parameters!$C$5*1000000 -> 4641.4235 | G47: =D47/Parameters!$C$5*1000000 -> 29.788235 | H47: =E47/Parameters!$C$5*1000000 -> 4.7058824 | I47: =2*A47*Parameters!$C$28*1000000 -> 1843.2 | J47: =A47*Parameters!$C$28*1000000 -> 921.6 | K47: =B47/(Parameters!$C$5*Parameters!$C$6)+D47/(Parameters!$C$5*Parameters!$C$7)+E47/(Parameters!$C$5*Parameters!$C$8) -> 46.444494 | L47: =K47+2*A47*Parameters!$C$28/Parameters!$C$6 -> 64.876494 | M47: =I47+F47 -> 6484.6235 | N47: =J47+F47 -> 5563.0235 | O47: =J47+F47+G47+H47 -> 5597.5176 | P47: =J47+F47+Parameters!$C$31*1000000 -> 5566.6235 | Q47: =Parameters!$C$6*1000000-N47 -> -5463.0235 | R47: =IF(M47<=Parameters!$C$6*1000000,1,0) -> 0 | S47: =IF(N47<=Parameters!$C$6*1000000,1,0) -> 0 | T47: =IF(K47<=Parameters!$C$12,1,0) -> 0 | U47: =C47/(Parameters!$C$5*Parameters!$C$6)+D47/(Parameters!$C$5*Parameters!$C$7)+E47/(Parameters!$C$5*Parameters!$C$8) -> 5.0026118
A50: Results
A51: N_max A1 — blocking comm, U_block ≤ U_max | G51: =SUMPRODUCT((L5:L41<=Parameters!$C$12)*1)+3 -> 12 | H51: largest N in 4..40 with U_block ≤ 1 (count of passes + 3)
A52: N_max A2 — single shared SPI bus, path ≤ T1 | G52: =SUMPRODUCT(R5:R41)+3 -> 12 | H52: path = 2N·t_SPI + C1/f_CPU
A53: N_max A2′ — one SPI bus per arm, path ≤ T1 | G53: =SUMPRODUCT(S5:S41)+3 -> 19 | H53: path = N·t_SPI + C1/f_CPU
A54: N_max A3 — parallel on-board ADC, U_DMA ≤ U_max | G54: =SUMPRODUCT(T5:T41)+3 -> 37 | H54: compute only: 12N²+10N+50 term
A55: N_max A3 closed form ≈ √(U_max·B1/c_CS) | G55: =SQRT(Parameters!$C$12*Parameters!$C$5*Parameters!$C$6/Parameters!$C$21) -> 37.638633 | H55: dominant-term approximation
A56: N_max A3 at U_design = 0.7 | G56: =SUMPRODUCT((K5:K41<=Parameters!$C$13)*1)+3 -> 30
A57: N = N_ref: C1 (cyc) | G57: =INDEX(B5:B47,MATCH(Parameters!$C$11,A5:A47,0)) -> 2900
A58: N = N_ref: t1 (µs) | G58: =INDEX(F5:F47,MATCH(Parameters!$C$11,A5:A47,0)) -> 17.058824
A59: N = N_ref: U_DMA | G59: =INDEX(K5:K47,MATCH(Parameters!$C$11,A5:A47,0)) -> 0.17391176 | H59: 17.39 % expected
A60: N = N_ref: U_block | G60: =INDEX(L5:L47,MATCH(Parameters!$C$11,A5:A47,0)) -> 1.2539118 | H60: 125 % expected → infeasible
A61: N = N_ref: comm fraction of deadline (dual) | G61: =INDEX(J5:J47,MATCH(Parameters!$C$11,A5:A47,0))/(Parameters!$C$6*1000000) -> 0.54 | H61: 54 % expected
A62: N = N_ref: path dual (µs) / slack (µs) | G62: =INDEX(N5:N47,MATCH(Parameters!$C$11,A5:A47,0)) -> 71.058824 | H62: 71.06 µs; slack in next row
G63: =INDEX(Q5:Q47,MATCH(Parameters!$C$11,A5:A47,0)) -> 28.941176 | H63: 28.94 µs
A64: N = N_ref: actuation latency (µs) | G64: =INDEX(P5:P47,MATCH(Parameters!$C$11,A5:A47,0)) -> 74.658824 | H64: 74.7 µs

Sheet §4 Case B
A1: §4 Case B — Centralized FPGA + Bitonic sorting network (Ricco et al. [1])
A2: M = 2^p ≥ N. CS = compare-and-swap element. Report sort latencies from [1] eq. (7) are inputs; the CS-count extrapolation is a formula.
A4: N (= M) | B4: p = log2 M | C4: CS elements = M·p(p+1)/4 | D4: Stages (depth) = p(p+1)/2 | E4: Acquisition (µs) = 2N·t_AUR | F4: Sort latency 2 arms (µs) — [1] eq.(7) input | G4: Sort cross-check (µs) = 2 arms·3 clk·stages/f_FPGA | H4: Total / T1 = (acq + sort + 0.2)/T1 | I4: LUT CS-count extrapolation = LUT_64·CS(M)/CS(64) | J4: LUT % of XC6SLX45 | K4: LUT % report value (input) | L4: LUT % of Artix-7 XC7A35T | M4: Feasible (LUT ≤ device)
A5: 8 | B5: =LOG(A5,2) -> 3 | C5: =A5*B5*(B5+1)/4 -> 24 | D5: =B5*(B5+1)/2 -> 6 | E5: =2*A5*Parameters!$C$30*1000000 -> 0.64 | F5: 0.36 | G5: =2*(3*D5)/Parameters!$C$37*1000000 -> 0.36 | H5: =(E5+F5+0.2)/(Parameters!$C$6*1000000) -> 0.012 | I5: =Parameters!$C$39*C5/($C$8) -> 221.42857 | J5: =I5/Parameters!$C$38 -> 0.0081145035 | K5: 0.015 | L5: =I5/Parameters!$C$40 -> 0.010645604 | M5: =IF(J5<=1,"yes","no") -> yes
A6: 16 | B6: =LOG(A6,2) -> 4 | C6: =A6*B6*(B6+1)/4 -> 80 | D6: =B6*(B6+1)/2 -> 10 | E6: =2*A6*Parameters!$C$30*1000000 -> 1.28 | F6: 0.44 | G6: =2*(3*D6)/Parameters!$C$37*1000000 -> 0.6 | H6: =(E6+F6+0.2)/(Parameters!$C$6*1000000) -> 0.0192 | I6: =Parameters!$C$39*C6/($C$8) -> 738.09524 | J6: =I6/Parameters!$C$38 -> 0.027048345 | K6: 0.03 | L6: =I6/Parameters!$C$40 -> 0.035485348 | M6: =IF(J6<=1,"yes","no") -> yes
A7: 32 | B7: =LOG(A7,2) -> 5 | C7: =A7*B7*(B7+1)/4 -> 240 | D7: =B7*(B7+1)/2 -> 15 | E7: =2*A7*Parameters!$C$30*1000000 -> 2.56 | F7: 0.64 | G7: =2*(3*D7)/Parameters!$C$37*1000000 -> 0.9 | H7: =(E7+F7+0.2)/(Parameters!$C$6*1000000) -> 0.034 | I7: =Parameters!$C$39*C7/($C$8) -> 2214.2857 | J7: =I7/Parameters!$C$38 -> 0.081145035 | K7: 0.08 | L7: =I7/Parameters!$C$40 -> 0.10645604 | M7: =IF(J7<=1,"yes","no") -> yes
A8: 64 | B8: =LOG(A8,2) -> 6 | C8: =A8*B8*(B8+1)/4 -> 672 | D8: =B8*(B8+1)/2 -> 21 | E8: =2*A8*Parameters!$C$30*1000000 -> 5.12 | F8: 0.88 | G8: =2*(3*D8)/Parameters!$C$37*1000000 -> 1.26 | H8: =(E8+F8+0.2)/(Parameters!$C$6*1000000) -> 0.062 | I8: =Parameters!$C$39*C8/($C$8) -> 6200 | J8: =I8/Parameters!$C$38 -> 0.2272061 | K8: 0.21 | L8: =I8/Parameters!$C$40 -> 0.29807692 | M8: =IF(J8<=1,"yes","no") -> yes
A9: 128 | B9: =LOG(A9,2) -> 7 | C9: =A9*B9*(B9+1)/4 -> 1792 | D9: =B9*(B9+1)/2 -> 28 | E9: =2*A9*Parameters!$C$30*1000000 -> 10.24 | F9: 1.16 | G9: =2*(3*D9)/Parameters!$C$37*1000000 -> 1.68 | H9: =(E9+F9+0.2)/(Parameters!$C$6*1000000) -> 0.116 | I9: =Parameters!$C$39*C9/($C$8) -> 16533.333 | J9: =I9/Parameters!$C$38 -> 0.60588293 | K9: 0.55 | L9: =I9/Parameters!$C$40 -> 0.79487179 | M9: =IF(J9<=1,"yes","no") -> yes
A10: 256 | B10: =LOG(A10,2) -> 8 | C10: =A10*B10*(B10+1)/4 -> 4608 | D10: =B10*(B10+1)/2 -> 36 | E10: =2*A10*Parameters!$C$30*1000000 -> 20.48 | F10: 1.48 | G10: =2*(3*D10)/Parameters!$C$37*1000000 -> 2.16 | H10: =(E10+F10+0.2)/(Parameters!$C$6*1000000) -> 0.2216 | I10: =Parameters!$C$39*C10/($C$8) -> 42514.286 | J10: =I10/Parameters!$C$38 -> 1.5579847 | K10: 1.35 | L10: =I10/Parameters!$C$40 -> 2.043956 | M10: =IF(J10<=1,"yes","no") -> no
A13: Notes
A14: Column G: 3 clk per stage at maximum factorization (18 clk for 6 stages, M = 8 [1]) — shown as a cross-check; column F (from [1]) is used in the report.
A15: Column H adds 0.2 µs for selection + gate output. Time utilization stays ≈ 2 % at M = 16: the scheduling question is void; the binding quantity is LUT (columns I–L).
A16: Column I extrapolates LUTs proportionally to the CS count from the validated M = 64 point (6,200 LUT for six arms); the report values (column K) come from eqs. (1)–(7) of [1] and differ slightly at large M.
A17: N_max(B) = largest M with LUT ≤ device: ≈ 128 on Spartan-6 class; on the Artix-7 XC7A35T the same network already occupies ≈ 70 % (column L) before aggregation and transceiver logic.

Sheet §5 Case C
A1: §5 Case C — Fully decentralized consensus control (per node, multi-rate)
A4: Per-node item | B4: Cycles | C4: Period (s) | D4: Time (µs) = C/f_CPU | E4: Utilization = C/(f_CPU·T) | F4: Equation
A5: τ1 consensus law + frame handling + gate decision | B5: =Parameters!$C$32 -> 970 | C5: =Parameters!$C$6 -> 0.0001 | D5: =B5/Parameters!$C$5*1000000 -> 5.7058824 | E5: =B5/(Parameters!$C$5*C5) -> 0.057058824 | F5: C1_C/(f_CPU·T1)
A6: τ2 arm-level replica | B6: =Parameters!$C$33 -> 220 | C6: =Parameters!$C$7 -> 0.001 | D6: =B6/Parameters!$C$5*1000000 -> 1.2941176 | E6: =B6/(Parameters!$C$5*C6) -> 0.0012941176 | F6: C2_C/(f_CPU·T2)
A7: τ3 outer replica / broadcast reception | B7: =Parameters!$C$34 -> 800 | C7: =Parameters!$C$8 -> 0.01 | D7: =B7/Parameters!$C$5*1000000 -> 4.7058824 | E7: =B7/(Parameters!$C$5*C7) -> 0.00047058824 | F7: C3_C/(f_CPU·T3)
A8: Total per-node utilization U_C | E8: =SUM(E5:E7) -> 0.058823529 | F8: Σ C_i/(f_CPU·T_i) — 5.88 %, independent of N
A9: UART frame time (µs) = 10·⌈b/8⌉/3e6 | D9: =Parameters!$C$29*1000000 -> 13.333333
A10: Neighbour comm, 2 links in parallel (µs) | D10: =D9 -> 13.333333 | E10: =D10/(Parameters!$C$6*1000000) -> 0.13333333 | F10: link occupancy, not CPU load
A11: Neighbour comm, serialized (µs) | D11: =2*D9 -> 26.666667
A12: Measurement → actuation (µs) = t_frame + t1 (distribution = 0) | D12: =D10+D5 -> 19.039216 | F12: ≈ 19.0 µs, invariant in N
A14: Where N enters: (i) consensus convergence on a ring, (ii) ring broadcast traversal of θ, ω from the leader
A15: N | B15: λ2 = 2(1 − cos 2π/N) | C15: (2π/N)² approximation | D15: τ_conv (ms) = T1/(k_v·λ2) | E15: τ_conv ≤ 50 ms ? | F15: L_broadcast (ms) = (N/2)(t_UART + t_fw) | G15: L ≤ T2 ? | H15: L ≤ T3 ?
A16: 4 | B16: =2*(1-COS(2*PI()/A16)) -> 2 | C16: =(2*PI()/A16)^2 -> 2.4674011 | D16: =Parameters!$C$6/(Parameters!$C$35*B16)*1000 -> 0.25 | E16: =IF(D16<=50,"yes","no") -> yes | F16: =A16/2*(Parameters!$C$29+Parameters!$C$36)*1000 -> 0.030006667 | G16: =IF(F16<=Parameters!$C$7*1000,"yes","no") -> yes | H16: =IF(F16<=Parameters!$C$8*1000,"yes","no") -> yes
A17: 8 | B17: =2*(1-COS(2*PI()/A17)) -> 0.58578644 | C17: =(2*PI()/A17)^2 -> 0.61685028 | D17: =Parameters!$C$6/(Parameters!$C$35*B17)*1000 -> 0.85355339 | E17: =IF(D17<=50,"yes","no") -> yes | F17: =A17/2*(Parameters!$C$29+Parameters!$C$36)*1000 -> 0.060013333 | G17: =IF(F17<=Parameters!$C$7*1000,"yes","no") -> yes | H17: =IF(F17<=Parameters!$C$8*1000,"yes","no") -> yes
A18: 12 | B18: =2*(1-COS(2*PI()/A18)) -> 0.26794919 | C18: =(2*PI()/A18)^2 -> 0.27415568 | D18: =Parameters!$C$6/(Parameters!$C$35*B18)*1000 -> 1.8660254 | E18: =IF(D18<=50,"yes","no") -> yes | F18: =A18/2*(Parameters!$C$29+Parameters!$C$36)*1000 -> 0.09002 | G18: =IF(F18<=Parameters!$C$7*1000,"yes","no") -> yes | H18: =IF(F18<=Parameters!$C$8*1000,"yes","no") -> yes
A19: 16 | B19: =2*(1-COS(2*PI()/A19)) -> 0.15224093 | C19: =(2*PI()/A19)^2 -> 0.15421257 | D19: =Parameters!$C$6/(Parameters!$C$35*B19)*1000 -> 3.2842678 | E19: =IF(D19<=50,"yes","no") -> yes | F19: =A19/2*(Parameters!$C$29+Parameters!$C$36)*1000 -> 0.12002667 | G19: =IF(F19<=Parameters!$C$7*1000,"yes","no") -> yes | H19: =IF(F19<=Parameters!$C$8*1000,"yes","no") -> yes
A20: 24 | B20: =2*(1-COS(2*PI()/A20)) -> 0.068148347 | C20: =(2*PI()/A20)^2 -> 0.068538919 | D20: =Parameters!$C$6/(Parameters!$C$35*B20)*1000 -> 7.3369351 | E20: =IF(D20<=50,"yes","no") -> yes | F20: =A20/2*(Parameters!$C$29+Parameters!$C$36)*1000 -> 0.18004 | G20: =IF(F20<=Parameters!$C$7*1000,"yes","no") -> yes | H20: =IF(F20<=Parameters!$C$8*1000,"yes","no") -> yes
A21: 32 | B21: =2*(1-COS(2*PI()/A21)) -> 0.038429439 | C21: =(2*PI()/A21)^2 -> 0.038553142 | D21: =Parameters!$C$6/(Parameters!$C$35*B21)*1000 -> 13.010859 | E21: =IF(D21<=50,"yes","no") -> yes | F21: =A21/2*(Parameters!$C$29+Parameters!$C$36)*1000 -> 0.24005333 | G21: =IF(F21<=Parameters!$C$7*1000,"yes","no") -> yes | H21: =IF(F21<=Parameters!$C$8*1000,"yes","no") -> yes
A22: 48 | B22: =2*(1-COS(2*PI()/A22)) -> 0.017110277 | C22: =(2*PI()/A22)^2 -> 0.01713473 | D22: =Parameters!$C$6/(Parameters!$C$35*B22)*1000 -> 29.222203 | E22: =IF(D22<=50,"yes","no") -> yes | F22: =A22/2*(Parameters!$C$29+Parameters!$C$36)*1000 -> 0.36008 | G22: =IF(F22<=Parameters!$C$7*1000,"yes","no") -> yes | H22: =IF(F22<=Parameters!$C$8*1000,"yes","no") -> yes
A23: 64 | B23: =2*(1-COS(2*PI()/A23)) -> 0.0096305467 | C23: =(2*PI()/A23)^2 -> 0.0096382855 | D23: =Parameters!$C$6/(Parameters!$C$35*B23)*1000 -> 51.918133 | E23: =IF(D23<=50,"yes","no") -> no | F23: =A23/2*(Parameters!$C$29+Parameters!$C$36)*1000 -> 0.48010667 | G23: =IF(F23<=Parameters!$C$7*1000,"yes","no") -> yes | H23: =IF(F23<=Parameters!$C$8*1000,"yes","no") -> yes
A24: 80 | B24: =2*(1-COS(2*PI()/A24)) -> 0.0061653325 | C24: =(2*PI()/A24)^2 -> 0.0061685028 | D24: =Parameters!$C$6/(Parameters!$C$35*B24)*1000 -> 81.098626 | E24: =IF(D24<=50,"yes","no") -> no | F24: =A24/2*(Parameters!$C$29+Parameters!$C$36)*1000 -> 0.60013333 | G24: =IF(F24<=Parameters!$C$7*1000,"yes","no") -> yes | H24: =IF(F24<=Parameters!$C$8*1000,"yes","no") -> yes
A25: 90 | B25: =2*(1-COS(2*PI()/A25)) -> 0.0048718995 | C25: =(2*PI()/A25)^2 -> 0.0048738787 | D25: =Parameters!$C$6/(Parameters!$C$35*B25)*1000 -> 102.62938 | E25: =IF(D25<=50,"yes","no") -> no | F25: =A25/2*(Parameters!$C$29+Parameters!$C$36)*1000 -> 0.67515 | G25: =IF(F25<=Parameters!$C$7*1000,"yes","no") -> yes | H25: =IF(F25<=Parameters!$C$8*1000,"yes","no") -> yes
A26: 96 | B26: =2*(1-COS(2*PI()/A26)) -> 0.0042821535 | C26: =(2*PI()/A26)^2 -> 0.0042836825 | D26: =Parameters!$C$6/(Parameters!$C$35*B26)*1000 -> 116.76368 | E26: =IF(D26<=50,"yes","no") -> no | F26: =A26/2*(Parameters!$C$29+Parameters!$C$36)*1000 -> 0.72016 | G26: =IF(F26<=Parameters!$C$7*1000,"yes","no") -> yes | H26: =IF(F26<=Parameters!$C$8*1000,"yes","no") -> yes
A27: 128 | B27: =2*(1-COS(2*PI()/A27)) -> 0.0024090876 | C27: =(2*PI()/A27)^2 -> 0.0024095714 | D27: =Parameters!$C$6/(Parameters!$C$35*B27)*1000 -> 207.54746 | E27: =IF(D27<=50,"yes","no") -> no | F27: =A27/2*(Parameters!$C$29+Parameters!$C$36)*1000 -> 0.96021333 | G27: =IF(F27<=Parameters!$C$7*1000,"yes","no") -> yes | H27: =IF(F27<=Parameters!$C$8*1000,"yes","no") -> yes
... A29: 256 | B29: =2*(1-COS(2*PI()/A29)) -> 0.00060236261 | C29: =(2*PI()/A29)^2 -> 0.00060239285 | D29: =Parameters!$C$6/(Parameters!$C$35*B29)*1000 -> 830.0648 | E29: =IF(D29<=50,"yes","no") -> no | F29: =A29/2*(Parameters!$C$29+Parameters!$C$36)*1000 -> 1.9204267 | G29: =IF(F29<=Parameters!$C$7*1000,"yes","no") -> no | H29: =IF(F29<=Parameters!$C$8*1000,"yes","no") -> yes
A31: N_max(C): largest N with τ_conv inside the capacitor-imbalance dynamics (tens of ms, here 50 ms) → 64–90 on a pure ring; chordal shortcuts raise λ2 and push beyond 256.

Sheet §6 Scaling laws
A1: §6 Computational scaling laws for N — layer cost per period (µs) for all variants
A4: N | B4: A: CVB bubble (µs) O(N²) | C4: A: CVB merge (µs) O(N log N) | D4: A: CVB ±1 min/max (µs) O(N) | E4: A: energy 200+19N (µs) O(N) | F4: outer 800 (µs) O(1) | G4: C: τ1 970 (µs) O(1) | H4: C: τ2 220 (µs) O(1) | I4: B: Bitonic latency 2 arms (µs) ≈ 2·3·p(p+1)/2 /f_FPGA | J4: T1 budget (µs) | K4: T1 at f_ctrl = 4·N·f0 (µs) (±1 rule) | L4: Acq single SPI (µs) O(N) | M4: Acq Aurora (µs) O(N) | N4: C: comm O(1) (µs)
A5: 4 | B5: =(Parameters!$C$21*A5*(A5-1)+2*Parameters!$C$22*A5+Parameters!$C$23)/Parameters!$C$5*1000000 -> 1.6588235 | C5: =(40*A5*LOG(A5,2)+10*A5+50)/Parameters!$C$5*1000000 -> 2.4117647 | D5: =(200+6*A5)/Parameters!$C$5*1000000 -> 1.3176471 | E5: =(Parameters!$C$24+Parameters!$C$25*A5)/Parameters!$C$5*1000000 -> 1.6235294 | F5: =Parameters!$C$26/Parameters!$C$5*1000000 -> 4.7058824 | G5: =Parameters!$C$32/Parameters!$C$5*1000000 -> 5.7058824 | H5: =Parameters!$C$33/Parameters!$C$5*1000000 -> 1.2941176 | I5: =2*3*(CEILING(LOG(A5,2),1)*(CEILING(LOG(A5,2),1)+1)/2)/Parameters!$C$37*1000000 -> 0.18 | J5: =Parameters!$C$6*1000000 -> 100 | K5: =1/(4*A5*Parameters!$C$9)*1000000 -> 1250 | L5: =2*A5*Parameters!$C$28*1000000 -> 28.8 | M5: =2*A5*Parameters!$C$30*1000000 -> 0.32 | N5: =Parameters!$C$29*1000000 -> 13.333333
A6: 5 | B6: =(Parameters!$C$21*A6*(A6-1)+2*Parameters!$C$22*A6+Parameters!$C$23)/Parameters!$C$5*1000000 -> 2.3529412 | C6: =(40*A6*LOG(A6,2)+10*A6+50)/Parameters!$C$5*1000000 -> 3.3199154 | D6: =(200+6*A6)/Parameters!$C$5*1000000 -> 1.3529412 | E6: =(Parameters!$C$24+Parameters!$C$25*A6)/Parameters!$C$5*1000000 -> 1.7352941 | F6: =Parameters!$C$26/Parameters!$C$5*1000000 -> 4.7058824 | G6: =Parameters!$C$32/Parameters!$C$5*1000000 -> 5.7058824 | H6: =Parameters!$C$33/Parameters!$C$5*1000000 -> 1.2941176 | I6: =2*3*(CEILING(LOG(A6,2),1)*(CEILING(LOG(A6,2),1)+1)/2)/Parameters!$C$37*1000000 -> 0.36 | J6: =Parameters!$C$6*1000000 -> 100 | K6: =1/(4*A6*Parameters!$C$9)*1000000 -> 1000 | L6: =2*A6*Parameters!$C$28*1000000 -> 36 | M6: =2*A6*Parameters!$C$30*1000000 -> 0.4 | N6: =Parameters!$C$29*1000000 -> 13.333333
A7: 6 | B7: =(Parameters!$C$21*A7*(A7-1)+2*Parameters!$C$22*A7+Parameters!$C$23)/Parameters!$C$5*1000000 -> 3.1882353 | C7: =(40*A7*LOG(A7,2)+10*A7+50)/Parameters!$C$5*1000000 -> 4.2964176 | D7: =(200+6*A7)/Parameters!$C$5*1000000 -> 1.3882353 | E7: =(Parameters!$C$24+Parameters!$C$25*A7)/Parameters!$C$5*1000000 -> 1.8470588 | F7: =Parameters!$C$26/Parameters!$C$5*1000000 -> 4.7058824 | G7: =Parameters!$C$32/Parameters!$C$5*1000000 -> 5.7058824 | H7: =Parameters!$C$33/Parameters!$C$5*1000000 -> 1.2941176 | I7: =2*3*(CEILING(LOG(A7,2),1)*(CEILING(LOG(A7,2),1)+1)/2)/Parameters!$C$37*1000000 -> 0.36 | J7: =Parameters!$C$6*1000000 -> 100 | K7: =1/(4*A7*Parameters!$C$9)*1000000 -> 833.33333 | L7: =2*A7*Parameters!$C$28*1000000 -> 43.2 | M7: =2*A7*Parameters!$C$30*1000000 -> 0.48 | N7: =Parameters!$C$29*1000000 -> 13.333333
A8: 7 | B8: =(Parameters!$C$21*A8*(A8-1)+2*Parameters!$C$22*A8+Parameters!$C$23)/Parameters!$C$5*1000000 -> 4.1647059 | C8: =(40*A8*LOG(A8,2)+10*A8+50)/Parameters!$C$5*1000000 -> 5.329761 | D8: =(200+6*A8)/Parameters!$C$5*1000000 -> 1.4235294 | E8: =(Parameters!$C$24+Parameters!$C$25*A8)/Parameters!$C$5*1000000 -> 1.9588235 | F8: =Parameters!$C$26/Parameters!$C$5*1000000 -> 4.7058824 | G8: =Parameters!$C$32/Parameters!$C$5*1000000 -> 5.7058824 | H8: =Parameters!$C$33/Parameters!$C$5*1000000 -> 1.2941176 | I8: =2*3*(CEILING(LOG(A8,2),1)*(CEILING(LOG(A8,2),1)+1)/2)/Parameters!$C$37*1000000 -> 0.36 | J8: =Parameters!$C$6*1000000 -> 100 | K8: =1/(4*A8*Parameters!$C$9)*1000000 -> 714.28571 | L8: =2*A8*Parameters!$C$28*1000000 -> 50.4 | M8: =2*A8*Parameters!$C$30*1000000 -> 0.56 | N8: =Parameters!$C$29*1000000 -> 13.333333
A9: 8 | B9: =(Parameters!$C$21*A9*(A9-1)+2*Parameters!$C$22*A9+Parameters!$C$23)/Parameters!$C$5*1000000 -> 5.2823529 | C9: =(40*A9*LOG(A9,2)+10*A9+50)/Parameters!$C$5*1000000 -> 6.4117647 | D9: =(200+6*A9)/Parameters!$C$5*1000000 -> 1.4588235 | E9: =(Parameters!$C$24+Parameters!$C$25*A9)/Parameters!$C$5*1000000 -> 2.0705882 | F9: =Parameters!$C$26/Parameters!$C$5*1000000 -> 4.7058824 | G9: =Parameters!$C$32/Parameters!$C$5*1000000 -> 5.7058824 | H9: =Parameters!$C$33/Parameters!$C$5*1000000 -> 1.2941176 | I9: =2*3*(CEILING(LOG(A9,2),1)*(CEILING(LOG(A9,2),1)+1)/2)/Parameters!$C$37*1000000 -> 0.36 | J9: =Parameters!$C$6*1000000 -> 100 | K9: =1/(4*A9*Parameters!$C$9)*1000000 -> 625 | L9: =2*A9*Parameters!$C$28*1000000 -> 57.6 | M9: =2*A9*Parameters!$C$30*1000000 -> 0.64 | N9: =Parameters!$C$29*1000000 -> 13.333333
A10: 9 | B10: =(Parameters!$C$21*A10*(A10-1)+2*Parameters!$C$22*A10+Parameters!$C$23)/Parameters!$C$5*1000000 -> 6.5411765 | C10: =(40*A10*LOG(A10,2)+10*A10+50)/Parameters!$C$5*1000000 -> 7.5363118 | D10: =(200+6*A10)/Parameters!$C$5*1000000 -> 1.4941176 | E10: =(Parameters!$C$24+Parameters!$C$25*A10)/Parameters!$C$5*1000000 -> 2.1823529 | F10: =Parameters!$C$26/Parameters!$C$5*1000000 -> 4.7058824 | G10: =Parameters!$C$32/Parameters!$C$5*1000000 -> 5.7058824 | H10: =Parameters!$C$33/Parameters!$C$5*1000000 -> 1.2941176 | I10: =2*3*(CEILING(LOG(A10,2),1)*(CEILING(LOG(A10,2),1)+1)/2)/Parameters!$C$37*1000000 -> 0.6 | J10: =Parameters!$C$6*1000000 -> 100 | K10: =1/(4*A10*Parameters!$C$9)*1000000 -> 555.55556 | L10: =2*A10*Parameters!$C$28*1000000 -> 64.8 | M10: =2*A10*Parameters!$C$30*1000000 -> 0.72 | N10: =Parameters!$C$29*1000000 -> 13.333333
A11: 10 | B11: =(Parameters!$C$21*A11*(A11-1)+2*Parameters!$C$22*A11+Parameters!$C$23)/Parameters!$C$5*1000000 -> 7.9411765 | C11: =(40*A11*LOG(A11,2)+10*A11+50)/Parameters!$C$5*1000000 -> 8.6986543 | D11: =(200+6*A11)/Parameters!$C$5*1000000 -> 1.5294118 | E11: =(Parameters!$C$24+Parameters!$C$25*A11)/Parameters!$C$5*1000000 -> 2.2941176 | F11: =Parameters!$C$26/Parameters!$C$5*1000000 -> 4.7058824 | G11: =Parameters!$C$32/Parameters!$C$5*1000000 -> 5.7058824 | H11: =Parameters!$C$33/Parameters!$C$5*1000000 -> 1.2941176 | I11: =2*3*(CEILING(LOG(A11,2),1)*(CEILING(LOG(A11,2),1)+1)/2)/Parameters!$C$37*1000000 -> 0.6 | J11: =Parameters!$C$6*1000000 -> 100 | K11: =1/(4*A11*Parameters!$C$9)*1000000 -> 500 | L11: =2*A11*Parameters!$C$28*1000000 -> 72 | M11: =2*A11*Parameters!$C$30*1000000 -> 0.8 | N11: =Parameters!$C$29*1000000 -> 13.333333
A12: 11 | B12: =(Parameters!$C$21*A12*(A12-1)+2*Parameters!$C$22*A12+Parameters!$C$23)/Parameters!$C$5*1000000 -> 9.4823529 | C12: =(40*A12*LOG(A12,2)+10*A12+50)/Parameters!$C$5*1000000 -> 9.8949995 | D12: =(200+6*A12)/Parameters!$C$5*1000000 -> 1.5647059 | E12: =(Parameters!$C$24+Parameters!$C$25*A12)/Parameters!$C$5*1000000 -> 2.4058824 | F12: =Parameters!$C$26/Parameters!$C$5*1000000 -> 4.7058824 | G12: =Parameters!$C$32/Parameters!$C$5*1000000 -> 5.7058824 | H12: =Parameters!$C$33/Parameters!$C$5*1000000 -> 1.2941176 | I12: =2*3*(CEILING(LOG(A12,2),1)*(CEILING(LOG(A12,2),1)+1)/2)/Parameters!$C$37*1000000 -> 0.6 | J12: =Parameters!$C$6*1000000 -> 100 | K12: =1/(4*A12*Parameters!$C$9)*1000000 -> 454.54545 | L12: =2*A12*Parameters!$C$28*1000000 -> 79.2 | M12: =2*A12*Parameters!$C$30*1000000 -> 0.88 | N12: =Parameters!$C$29*1000000 -> 13.333333
A13: 12 | B13: =(Parameters!$C$21*A13*(A13-1)+2*Parameters!$C$22*A13+Parameters!$C$23)/Parameters!$C$5*1000000 -> 11.164706 | C13: =(40*A13*LOG(A13,2)+10*A13+50)/Parameters!$C$5*1000000 -> 11.122247 | D13: =(200+6*A13)/Parameters!$C$5*1000000 -> 1.6 | E13: =(Parameters!$C$24+Parameters!$C$25*A13)/Parameters!$C$5*1000000 -> 2.5176471 | F13: =Parameters!$C$26/Parameters!$C$5*1000000 -> 4.7058824 | G13: =Parameters!$C$32/Parameters!$C$5*1000000 -> 5.7058824 | H13: =Parameters!$C$33/Parameters!$C$5*1000000 -> 1.2941176 | I13: =2*3*(CEILING(LOG(A13,2),1)*(CEILING(LOG(A13,2),1)+1)/2)/Parameters!$C$37*1000000 -> 0.6 | J13: =Parameters!$C$6*1000000 -> 100 | K13: =1/(4*A13*Parameters!$C$9)*1000000 -> 416.66667 | L13: =2*A13*Parameters!$C$28*1000000 -> 86.4 | M13: =2*A13*Parameters!$C$30*1000000 -> 0.96 | N13: =Parameters!$C$29*1000000 -> 13.333333
A14: 13 | B14: =(Parameters!$C$21*A14*(A14-1)+2*Parameters!$C$22*A14+Parameters!$C$23)/Parameters!$C$5*1000000 -> 12.988235 | C14: =(40*A14*LOG(A14,2)+10*A14+50)/Parameters!$C$5*1000000 -> 12.377816 | D14: =(200+6*A14)/Parameters!$C$5*1000000 -> 1.6352941 | E14: =(Parameters!$C$24+Parameters!$C$25*A14)/Parameters!$C$5*1000000 -> 2.6294118 | F14: =Parameters!$C$26/Parameters!$C$5*1000000 -> 4.7058824 | G14: =Parameters!$C$32/Parameters!$C$5*1000000 -> 5.7058824 | H14: =Parameters!$C$33/Parameters!$C$5*1000000 -> 1.2941176 | I14: =2*3*(CEILING(LOG(A14,2),1)*(CEILING(LOG(A14,2),1)+1)/2)/Parameters!$C$37*1000000 -> 0.6 | J14: =Parameters!$C$6*1000000 -> 100 | K14: =1/(4*A14*Parameters!$C$9)*1000000 -> 384.61538 | L14: =2*A14*Parameters!$C$28*1000000 -> 93.6 | M14: =2*A14*Parameters!$C$30*1000000 -> 1.04 | N14: =Parameters!$C$29*1000000 -> 13.333333
A15: 14 | B15: =(Parameters!$C$21*A15*(A15-1)+2*Parameters!$C$22*A15+Parameters!$C$23)/Parameters!$C$5*1000000 -> 14.952941 | C15: =(40*A15*LOG(A15,2)+10*A15+50)/Parameters!$C$5*1000000 -> 13.659522 | D15: =(200+6*A15)/Parameters!$C$5*1000000 -> 1.6705882 | E15: =(Parameters!$C$24+Parameters!$C$25*A15)/Parameters!$C$5*1000000 -> 2.7411765 | F15: =Parameters!$C$26/Parameters!$C$5*1000000 -> 4.7058824 | G15: =Parameters!$C$32/Parameters!$C$5*1000000 -> 5.7058824 | H15: =Parameters!$C$33/Parameters!$C$5*1000000 -> 1.2941176 | I15: =2*3*(CEILING(LOG(A15,2),1)*(CEILING(LOG(A15,2),1)+1)/2)/Parameters!$C$37*1000000 -> 0.6 | J15: =Parameters!$C$6*1000000 -> 100 | K15: =1/(4*A15*Parameters!$C$9)*1000000 -> 357.14286 | L15: =2*A15*Parameters!$C$28*1000000 -> 100.8 | M15: =2*A15*Parameters!$C$30*1000000 -> 1.12 | N15: =Parameters!$C$29*1000000 -> 13.333333
A16: 15 | B16: =(Parameters!$C$21*A16*(A16-1)+2*Parameters!$C$22*A16+Parameters!$C$23)/Parameters!$C$5*1000000 -> 17.058824 | C16: =(40*A16*LOG(A16,2)+10*A16+50)/Parameters!$C$5*1000000 -> 14.965496 | D16: =(200+6*A16)/Parameters!$C$5*1000000 -> 1.7058824 | E16: =(Parameters!$C$24+Parameters!$C$25*A16)/Parameters!$C$5*1000000 -> 2.8529412 | F16: =Parameters!$C$26/Parameters!$C$5*1000000 -> 4.7058824 | G16: =Parameters!$C$32/Parameters!$C$5*1000000 -> 5.7058824 | H16: =Parameters!$C$33/Parameters!$C$5*1000000 -> 1.2941176 | I16: =2*3*(CEILING(LOG(A16,2),1)*(CEILING(LOG(A16,2),1)+1)/2)/Parameters!$C$37*1000000 -> 0.6 | J16: =Parameters!$C$6*1000000 -> 100 | K16: =1/(4*A16*Parameters!$C$9)*1000000 -> 333.33333 | L16: =2*A16*Parameters!$C$28*1000000 -> 108 | M16: =2*A16*Parameters!$C$30*1000000 -> 1.2 | N16: =Parameters!$C$29*1000000 -> 13.333333
... A47: 256 | B47: =(Parameters!$C$21*A47*(A47-1)+2*Parameters!$C$22*A47+Parameters!$C$23)/Parameters!$C$5*1000000 -> 4641.4235 | C47: =(40*A47*LOG(A47,2)+10*A47+50)/Parameters!$C$5*1000000 -> 497.23529 | D47: =(200+6*A47)/Parameters!$C$5*1000000 -> 10.211765 | E47: =(Parameters!$C$24+Parameters!$C$25*A47)/Parameters!$C$5*1000000 -> 29.788235 | F47: =Parameters!$C$26/Parameters!$C$5*1000000 -> 4.7058824 | G47: =Parameters!$C$32/Parameters!$C$5*1000000 -> 5.7058824 | H47: =Parameters!$C$33/Parameters!$C$5*1000000 -> 1.2941176 | I47: =2*3*(CEILING(LOG(A47,2),1)*(CEILING(LOG(A47,2),1)+1)/2)/Parameters!$C$37*1000000 -> 2.16 | J47: =Parameters!$C$6*1000000 -> 100 | K47: =1/(4*A47*Parameters!$C$9)*1000000 -> 19.53125 | L47: =2*A47*Parameters!$C$28*1000000 -> 1843.2 | M47: =2*A47*Parameters!$C$30*1000000 -> 20.48 | N47: =Parameters!$C$29*1000000 -> 13.333333
A50: Table 6.2 reference values (formulas)
A51: Quantity | B51: A : MCU + bubble @N_ref | C51: B : FPGA M=16 | D51: C : per node | E51: Equation
A52: C1 (cyc) | B52: =Parameters!$C$21*Parameters!$C$11*(Parameters!$C$11-1)+2*Parameters!$C$22*Parameters!$C$11+Parameters!$C$23 -> 2900 | C52: ='§4 Case B'!D6*3*2 -> 60 | D52: =Parameters!$C$32 -> 970 | E52: A: 12N²+10N+50 · B: clk = 2 arms × 3 clk × stages · C: const
A53: C2 (cyc) | B53: =Parameters!$C$24+Parameters!$C$25*Parameters!$C$11 -> 485 | C53: adder tree | D53: =Parameters!$C$33 -> 220 | E53: 200+19N / O(N) HW / const
A54: C3 (cyc) | B54: =Parameters!$C$26 -> 800 | C54: pipelined | D54: =Parameters!$C$34 -> 800 | E54: O(1)
A55: Acq / comm (µs) | B55: =Parameters!$C$11*Parameters!$C$28*1000000 -> 54 | C55: =2*Parameters!$C$11*Parameters!$C$30*1000000 -> 1.2 | D55: =Parameters!$C$29*1000000 -> 13.333333 | E55: N·t_SPI dual bus / 2N·40 ns / one UART frame
A56: U | B56: =INDEX('§3 Case A'!K5:K47,MATCH(Parameters!C11,'§3 Case A'!A5:A47,0)) -> 0.17391176 | C56: ='§4 Case B'!H6 -> 0.0192 | D56: ='§5 Case C'!E8 -> 0.058823529 | E56: Σ C_i/(f_CPU·T_i)
A57: N_max | B57: ='§3 Case A'!G52 -> 12 | C57: 128 | D57: =64 -> 64 | E57: path rule / LUT rule / convergence rule

Sheet §7 Scheduling
A1: §7 Rate-Monotonic schedulability and response-time analysis (Case A at N_ref)
A4: n tasks | B4: 3
A5: Liu–Layland bound n(2^(1/n) − 1) | B5: =B4*(2^(1/B4)-1) -> 0.77976315 | C5: [12] — 78.0 % for n = 3
A6: Harmonic-period bound | B6: =Parameters!$C$12 -> 1 | C6: T2/T1 and T3/T2 integers → 100 %
A7: T2/T1 | B7: =Parameters!$C$7/Parameters!$C$6 -> 10
A8: T3/T2 | B8: =Parameters!$C$8/Parameters!$C$7 -> 10
A10: Task | B10: C (µs) | C10: T (µs) | D10: U_i
A11: τ1 CVB | B11: =INDEX('§3 Case A'!F5:F47,MATCH(Parameters!C11,'§3 Case A'!A5:A47,0)) -> 17.058824 | C11: =Parameters!$C$6*1000000 -> 100 | D11: =B11/C11 -> 0.17058824
A12: τ2 energy | B12: =INDEX('§3 Case A'!G5:G47,MATCH(Parameters!C11,'§3 Case A'!A5:A47,0)) -> 2.8529412 | C12: =Parameters!$C$7*1000000 -> 1000 | D12: =B12/C12 -> 0.0028529412
A13: τ3 outer | B13: =INDEX('§3 Case A'!H5:H47,MATCH(Parameters!C11,'§3 Case A'!A5:A47,0)) -> 4.7058824 | C13: =Parameters!$C$8*1000000 -> 10000 | D13: =B13/C13 -> 0.00047058824
A14: U total | D14: =SUM(D11:D13) -> 0.17391176 | E14: =IF(D14<=B6,"schedulable (RMS, harmonic)","not schedulable") -> schedulable (RMS, harmonic)
A16: Response time of τ3: R = C3 + ⌈R/T1⌉·C1 + ⌈R/T2⌉·C2 (fixed-point iteration)
A17: Iteration | B17: R_k (µs) | C17: R_{k+1} (µs) | D17: converged?
A18: 0 | B18: =B13 -> 4.7058824 | C18: =B13+CEILING(B18/C11,1)*B11+CEILING(B18/C12,1)*B12 -> 24.617647 | D18: =IF(ABS(C18-B18)<0.0001,"yes","no") -> no
A19: 1 | B19: =C18 -> 24.617647 | C19: =B13+CEILING(B19/C11,1)*B11+CEILING(B19/C12,1)*B12 -> 24.617647 | D19: =IF(ABS(C19-B19)<0.0001,"yes","no") -> yes
A20: 2 | B20: =C19 -> 24.617647 | C20: =B13+CEILING(B20/C11,1)*B11+CEILING(B20/C12,1)*B12 -> 24.617647 | D20: =IF(ABS(C20-B20)<0.0001,"yes","no") -> yes
A21: 3 | B21: =C20 -> 24.617647 | C21: =B13+CEILING(B21/C11,1)*B11+CEILING(B21/C12,1)*B12 -> 24.617647 | D21: =IF(ABS(C21-B21)<0.0001,"yes","no") -> yes
A22: 4 | B22: =C21 -> 24.617647 | C22: =B13+CEILING(B22/C11,1)*B11+CEILING(B22/C12,1)*B12 -> 24.617647 | D22: =IF(ABS(C22-B22)<0.0001,"yes","no") -> yes
A24: Worst-case response time of τ3 (µs) = 17.06 + 2.85 + 4.71 ≈ 24.7 | B24: =C22 -> 24.617647
A25: Utilization ceiling retained for the project | B25: =Parameters!$C$13 -> 0.7 | C25: reserve for communication DMA service

Sheet §8 Comparative
A1: §8 Comparative results — N_max and verdicts (pulled from the case sheets)
A4: Criterion | B4: A : MCU + bubble | C4: B : FPGA + Bitonic | D4: C : Decentralized | E4: Rule / equation
A5: Binding wall | B5: communication path, then O(N²) compute | C5: LUT resources O(N·log²N) | D5: consensus convergence O(N²) | E5: see §6
A6: N_max — shared bus / path | B6: ='§3 Case A'!G52 -> 12 | C6: n/a | D6: n/a | E6: 2N·t_SPI + C1/f_CPU ≤ T1
A7: N_max — one bus per arm | B7: ='§3 Case A'!G53 -> 19 | C7: n/a | D7: n/a | E7: N·t_SPI + C1/f_CPU ≤ T1
A8: N_max — compute only / resources | B8: ='§3 Case A'!G54 -> 37 | C8: 128 | D8: n/a | E8: U ≤ 1 / LUT ≤ device
A9: N_max — dynamics (pure ring, τ ≤ 50 ms) | B9: n/a | C9: n/a | D9: =INDEX('§5 Case C'!A16:A29,SUMPRODUCT(('§5 Case C'!D16:D29<=50)*1)) -> 48 | E9: largest N of the sweep with τ_conv ≤ 50 ms (report: 64–90)
A10: U at N_ref / per node | B10: =INDEX('§3 Case A'!K5:K47,MATCH(Parameters!C11,'§3 Case A'!A5:A47,0)) -> 0.17391176 | C10: ='§4 Case B'!H6 -> 0.0192 | D10: ='§5 Case C'!E8 -> 0.058823529 | E10: Σ C_i/(f_CPU·T_i)
A11: Comm fraction of T1 at N_ref | B11: =INDEX('§3 Case A'!J5:J47,MATCH(Parameters!C11,'§3 Case A'!A5:A47,0))/100 -> 0.54 | C11: ='§4 Case B'!E6/100 -> 0.0128 | D11: ='§5 Case C'!E10 -> 0.13333333 | E11: T_acq / T1
A12: Actuation latency (µs) | B12: =INDEX('§3 Case A'!P5:P47,MATCH(Parameters!C11,'§3 Case A'!A5:A47,0)) -> 74.658824 | C12: ='§4 Case B'!E6+'§4 Case B'!F6+0.2 -> 1.92 | D12: ='§5 Case C'!D12 -> 19.039216 | E12: T_acq + t1 + T_dist
A13: Single point of failure | B13: yes (controller + bus) | C13: yes (FPGA + link) | D13: no (bypass + renumbering)
A14: Cost / openness | B14: lowest, open | C14: highest, vendor-bound | D14: moderate, open, per module

Sheet §9 Harmonics
A1: §9 Harmonic and synchronization considerations
A4: N | B4: THD_q = k_THD/N | C4: meets 5 % (IEEE 519) | D4: meets 3 % | E4: f_ctrl ≥ 4·N·f0 (kHz) — ±1 rule | F4: avg device switching ≤ f_ctrl/N + 8·f0 (Hz)
A5: 4 | B5: =Parameters!$C$41/A5 -> 0.204 | C5: =IF(B5<=0.05,"yes","no") -> no | D5: =IF(B5<=0.03,"yes","no") -> no | E5: =4*A5*Parameters!$C$9/1000 -> 0.8 | F5: =E5*1000/A5+8*Parameters!$C$9 -> 600
A6: 5 | B6: =Parameters!$C$41/A6 -> 0.1632 | C6: =IF(B6<=0.05,"yes","no") -> no | D6: =IF(B6<=0.03,"yes","no") -> no | E6: =4*A6*Parameters!$C$9/1000 -> 1 | F6: =E6*1000/A6+8*Parameters!$C$9 -> 600
A7: 8 | B7: =Parameters!$C$41/A7 -> 0.102 | C7: =IF(B7<=0.05,"yes","no") -> no | D7: =IF(B7<=0.03,"yes","no") -> no | E7: =4*A7*Parameters!$C$9/1000 -> 1.6 | F7: =E7*1000/A7+8*Parameters!$C$9 -> 600
A8: 12 | B8: =Parameters!$C$41/A8 -> 0.068 | C8: =IF(B8<=0.05,"yes","no") -> no | D8: =IF(B8<=0.03,"yes","no") -> no | E8: =4*A8*Parameters!$C$9/1000 -> 2.4 | F8: =E8*1000/A8+8*Parameters!$C$9 -> 600
A9: 15 | B9: =Parameters!$C$41/A9 -> 0.0544 | C9: =IF(B9<=0.05,"yes","no") -> no | D9: =IF(B9<=0.03,"yes","no") -> no | E9: =4*A9*Parameters!$C$9/1000 -> 3 | F9: =E9*1000/A9+8*Parameters!$C$9 -> 600
A10: 16 | B10: =Parameters!$C$41/A10 -> 0.051 | C10: =IF(B10<=0.05,"yes","no") -> no | D10: =IF(B10<=0.03,"yes","no") -> no | E10: =4*A10*Parameters!$C$9/1000 -> 3.2 | F10: =E10*1000/A10+8*Parameters!$C$9 -> 600
A11: 20 | B11: =Parameters!$C$41/A11 -> 0.0408 | C11: =IF(B11<=0.05,"yes","no") -> yes | D11: =IF(B11<=0.03,"yes","no") -> no | E11: =4*A11*Parameters!$C$9/1000 -> 4 | F11: =E11*1000/A11+8*Parameters!$C$9 -> 600
A12: 24 | B12: =Parameters!$C$41/A12 -> 0.034 | C12: =IF(B12<=0.05,"yes","no") -> yes | D12: =IF(B12<=0.03,"yes","no") -> no | E12: =4*A12*Parameters!$C$9/1000 -> 4.8 | F12: =E12*1000/A12+8*Parameters!$C$9 -> 600
A13: 27 | B13: =Parameters!$C$41/A13 -> 0.030222222 | C13: =IF(B13<=0.05,"yes","no") -> yes | D13: =IF(B13<=0.03,"yes","no") -> no | E13: =4*A13*Parameters!$C$9/1000 -> 5.4 | F13: =E13*1000/A13+8*Parameters!$C$9 -> 600
A14: 28 | B14: =Parameters!$C$41/A14 -> 0.029142857 | C14: =IF(B14<=0.05,"yes","no") -> yes | D14: =IF(B14<=0.03,"yes","no") -> yes | E14: =4*A14*Parameters!$C$9/1000 -> 5.6 | F14: =E14*1000/A14+8*Parameters!$C$9 -> 600
A15: 32 | B15: =Parameters!$C$41/A15 -> 0.0255 | C15: =IF(B15<=0.05,"yes","no") -> yes | D15: =IF(B15<=0.03,"yes","no") -> yes | E15: =4*A15*Parameters!$C$9/1000 -> 6.4 | F15: =E15*1000/A15+8*Parameters!$C$9 -> 600
A16: 48 | B16: =Parameters!$C$41/A16 -> 0.017 | C16: =IF(B16<=0.05,"yes","no") -> yes | D16: =IF(B16<=0.03,"yes","no") -> yes | E16: =4*A16*Parameters!$C$9/1000 -> 9.6 | F16: =E16*1000/A16+8*Parameters!$C$9 -> 600
A17: 64 | B17: =Parameters!$C$41/A17 -> 0.01275 | C17: =IF(B17<=0.05,"yes","no") -> yes | D17: =IF(B17<=0.03,"yes","no") -> yes | E17: =4*A17*Parameters!$C$9/1000 -> 12.8 | F17: =E17*1000/A17+8*Parameters!$C$9 -> 600
A19: N_min for 5 % = k_THD/0.05 | E19: =Parameters!$C$41/0.05 -> 16.32 | F19: ≈ 16.3 → N ≥ 17 strictly, N ≈ 16 in the report
A20: N_min for 3 % = k_THD/0.03 | E20: =Parameters!$C$41/0.03 -> 27.2 | F20: ≈ 27.2
A21: Dead-time distortion ΔD = 2·t_d·f_c (PWM variants) | E21: =2*Parameters!$C$42*Parameters!$C$43 -> 0.04 | F21: negligible for NLM (device switching ~ f0 class)
A22: Rotation tones (Case C): f_step = 1/(HOLD·T1), f_step/N — HOLD = | E22: 1 | F22: =1/(E22*Parameters!$C$6) -> 10000 | G22: Hz = f_step
A23: Scan skew error ΔV = i·ΔT/C (A: sequential sampling of 2N channels) — i (A), ΔT (s), C (F): | E23: 10 | F23: 5.4e-05 | G23: 0.0022 | H23: =E23*F23/G23*1000 -> 245.45455 | I23: mV
A24: Window collision: harmonic lower bound N ≥ 16 vs Case-A shared-bus upper bound | E24: ='§3 Case A'!G52 -> 12 | F24: =IF(E24<CEILING(Parameters!$C$41/0.05,1),"empty window on a shared bus","window exists") -> empty window on a shared bus
